{
  "processed_files": [
    {
      "filepath": "app/services/ai_service.py",
      "coverage": 5.0,
      "target_item": "generate_response",
      "target_type": "method",
      "test_generated": true,
      "test_saved": true,
      "test_result": {
        "success": false,
        "stdout": "============================= test session starts ==============================\nplatform linux -- Python 3.10.18, pytest-7.4.3, pluggy-1.6.0 -- /opt/hostedtoolcache/Python/3.10.18/x64/bin/python\ncachedir: .pytest_cache\nrootdir: /home/runner/work/ai-product-qa/ai-product-qa\nplugins: anyio-4.9.0, cov-4.1.0, asyncio-0.23.6\nasyncio: mode=strict\ncollecting ... collected 0 items / 1 error\n\n==================================== ERRORS ====================================\n__________________ ERROR collecting tests/test_ai_service.py ___________________\n/opt/hostedtoolcache/Python/3.10.18/x64/lib/python3.10/site-packages/_pytest/runner.py:341: in from_call\n    result: Optional[TResult] = func()\n/opt/hostedtoolcache/Python/3.10.18/x64/lib/python3.10/site-packages/_pytest/runner.py:372: in <lambda>\n    call = CallInfo.from_call(lambda: list(collector.collect()), \"collect\")\n/opt/hostedtoolcache/Python/3.10.18/x64/lib/python3.10/site-packages/pytest_asyncio/plugin.py:640: in _patched_collect\n    module = collector.obj\n/opt/hostedtoolcache/Python/3.10.18/x64/lib/python3.10/site-packages/_pytest/python.py:310: in obj\n    self._obj = obj = self._getobj()\n/opt/hostedtoolcache/Python/3.10.18/x64/lib/python3.10/site-packages/_pytest/python.py:528: in _getobj\n    return self._importtestmodule()\n/opt/hostedtoolcache/Python/3.10.18/x64/lib/python3.10/site-packages/_pytest/python.py:617: in _importtestmodule\n    mod = import_path(self.path, mode=importmode, root=self.config.rootpath)\n/opt/hostedtoolcache/Python/3.10.18/x64/lib/python3.10/site-packages/_pytest/pathlib.py:567: in import_path\n    importlib.import_module(module_name)\n/opt/hostedtoolcache/Python/3.10.18/x64/lib/python3.10/importlib/__init__.py:126: in import_module\n    return _bootstrap._gcd_import(name[level:], package, level)\n<frozen importlib._bootstrap>:1050: in _gcd_import\n    ???\n<frozen importlib._bootstrap>:1027: in _find_and_load\n    ???\n<frozen importlib._bootstrap>:1006: in _find_and_load_unlocked\n    ???\n<frozen importlib._bootstrap>:688: in _load_unlocked\n    ???\n/opt/hostedtoolcache/Python/3.10.18/x64/lib/python3.10/site-packages/_pytest/assertion/rewrite.py:186: in exec_module\n    exec(co, module.__dict__)\ntests/test_ai_service.py:3: in <module>\n    from app.services.ai_service import AIService\napp/services/ai_service.py:3: in <module>\n    from app.utils.config import get_settings\napp/utils/config.py:30: in <module>\n    settings = get_settings()\napp/utils/config.py:28: in get_settings\n    return Settings()\napp/utils/config.py:21: in __init__\n    super().__init__(**kwargs)\n/opt/hostedtoolcache/Python/3.10.18/x64/lib/python3.10/site-packages/pydantic_settings/main.py:176: in __init__\n    super().__init__(\nE   pydantic_core._pydantic_core.ValidationError: 1 validation error for Settings\nE   GOOGLE_API_KEY\nE     Field required [type=missing, input_value={}, input_type=dict]\nE       For further information visit https://errors.pydantic.dev/2.11/v/missing\n=============================== warnings summary ===============================\n../../../../../opt/hostedtoolcache/Python/3.10.18/x64/lib/python3.10/site-packages/pydantic/_internal/_config.py:323\n  /opt/hostedtoolcache/Python/3.10.18/x64/lib/python3.10/site-packages/pydantic/_internal/_config.py:323: PydanticDeprecatedSince20: Support for class-based `config` is deprecated, use ConfigDict instead. Deprecated in Pydantic V2.0 to be removed in V3.0. See Pydantic V2 Migration Guide at https://errors.pydantic.dev/2.11/migration/\n    warnings.warn(DEPRECATION_MESSAGE, DeprecationWarning)\n\n-- Docs: https://docs.pytest.org/en/stable/how-to/capture-warnings.html\n=========================== short test summary info ============================\nERROR tests/test_ai_service.py - pydantic_core._pydantic_core.ValidationError: 1 validation error for Settings\nGOOGLE_API_KEY\n  Field required [type=missing, input_value={}, input_type=dict]\n    For further information visit https://errors.pydantic.dev/2.11/v/missing\n!!!!!!!!!!!!!!!!!!!! Interrupted: 1 error during collection !!!!!!!!!!!!!!!!!!!!\n========================= 1 warning, 1 error in 0.81s ==========================\n",
        "stderr": "",
        "returncode": 2
      },
      "strategy": "single_function_focus",
      "attempts": 3
    }
  ],
  "success_count": 0,
  "error_count": 1,
  "strategy": "single_function_focus"
}