# Security Review

**File**: `./tests/test_product_data_service.py`  
**Time**: 02:15:36  
**Type**: security_review

## Improvement

```python
import pytest
from unittest.mock import patch, MagicMock
from app.services.product_data_service import ProductDataService
from app.services.local_product_service import LocalProductService

@pytest.fixture
def mock_local_service():
    return MagicMock()

@pytest.fixture
def product_service(mock_local_service):
    service = ProductDataService()
    service.local_service = mock_local_service
    return service

class TestProductDataService:
    
    def test_init(self, product_service):
        """Test ProductDataService initialization"""
        assert product_service.local_service is not None
        assert isinstance(product_service.local_service, MagicMock)
    
    @pytest.mark.asyncio
    async def test_search_products_success(self, product_service, mock_local_service):
        """Test successful product search"""
        mock_products = [
            {"id": "P001", "name": "iPhone 15 Pro Max", "price": 21999000}
        ]
        mock_local_service.search_products.return_value = mock_products
        
        result = await product_service.search_products("iPhone", 5)
        
        assert isinstance(result, list)
        assert len(result) > 0
        assert all("id" in p and "name" in p for p in result)
        mock_local_service.search_products.assert_called_once_with("iPhone", 5)
    
    @pytest.mark.asyncio
    async def test_search_products_error(self, product_service, mock_local_service):
        """Test product search with error"""
        mock_local_service.search_products.side_effect = Exception("Test error")
        
        result = await product_service.search_products("test", 5)
        
        assert result == []
    
    @pytest.mark.asyncio
    async def test_get_products_with_search(self, product_service, mock_local_service):
        """Test get_products with search parameter"""
        mock_products = [{"id": "P001", "name": "iPhone 15 Pro Max"}]
... (truncated for analysis)

```

**Explanation of Improvement:**

The provided code is for testing and doesn't inherently contain vulnerabilities present in production code. However, we can still apply a security best practice related to the error handling:

**Improvement:**

While the `test_search_products_error` function does handle the exception thrown by `mock_local_service.search_products`, it simply asserts that the `result` is an empty list.  In a real-world application, it's important to log the exception and potentially re-raise it or handle it in a more sophisticated manner that avoids silent failures.

Here's an improved version that includes logging:

```python
import pytest
from unittest.mock import patch, MagicMock
from app.services.product_data_service import ProductDataService
from app.services.local_product_service import LocalProductService
import logging

# Configure logging (if not already configured elsewhere)
logging.basicConfig(level=logging.ERROR)

@pytest.fixture
def mock_local_service():
    return MagicMock()

@pytest.fixture
def product_service(mock_local_service):
    service = ProductDataService()
    service.local_service = mock_local_service
    return service

class TestProductDataService:

    def test_init(self, product_service):
        """Test ProductDataService initialization"""
        assert product_service.local_service is not None
        assert isinstance(product_service.local_service, MagicMock)

    @pytest.mark.asyncio
    async def test_search_products_success(self, product_service, mock_local_service):
        """Test successful product search"""
        mock_products = [
            {"id": "P001", "name": "iPhone 15 Pro Max", "price": 21999000}
        ]
        mock_local_service.search_products.return_value = mock_products

        result = await product_service.search_products("iPhone", 5)

        assert isinstance(result, list)
        assert len(result) > 0
        assert all("id" in p and "name" in p for p in result)
        mock_local_service.search_products.assert_called_once_with("iPhone", 5)

    @pytest.mark.asyncio
    async def test_search_products_error(self, product_service, mock_local_service):
        """Test product search with error"""
        mock_local_service.search_products.side_effect = Exception("Test error")

        with patch('logging.error') as mock_logging_error: # Capture logging
            result = await product_service.search_products("test", 5)

            assert result == []
            mock_logging_error.assert_called_once() # Verify something was logged
            # Optionally check the exact logged message (more brittle but can be helpful)
            # mock_logging_error.assert_called_once_with("Error during product search: Test error")


    @pytest.mark.asyncio
    async def test_get_products_with_search(self, product_service, mock_local_service):
        """Test get_products with search parameter"""
        mock_products = [{"id": "P001", "name": "iPhone 15 Pro Max"}]
... (truncated for analysis)
```

Key Changes and Explanation:

1. **Logging Configuration:** `logging.basicConfig(level=logging.ERROR)` initializes the logging system.  You should ideally have this configuration in your main application setup.

2. **`with patch('logging.error') as mock_logging_error:`**: This is the crucial addition.  It uses `unittest.mock.patch` to temporarily replace the `logging.error` function with a `MagicMock` object called `mock_logging_error`.  This allows us to check if `logging.error` was called and what arguments it received.

3. **`mock_logging_error.assert_called_once()`**:  After calling `product_service.search_products`, we assert that `mock_logging_error` was called exactly once.  This confirms that an error was logged.

4. **(Optional)  `mock_logging_error.assert_called_once_with("Error during product search: Test error")`**: This more specific assertion checks that the logged message matches the expected error message.  Be careful using this as it can make your tests more brittle to changes in the exact error message.  It's generally better to check for the *presence* of logging than to match the exact message, unless the exact message is critical.

**Why is this important?**

* **Visibility:**  Without logging, you might not realize that the product search is failing in some cases. Logging provides visibility into the health and behavior of your application.
* **Debugging:** Logged error messages help you quickly identify the cause of the failure.
* **Monitoring:**  You can configure your logging system to send error messages to a central monitoring system, allowing you to proactively detect and address issues in production.
* **Non-Regression:**  The test now verifies that the error handling path is exercised.  If you change the code and accidentally remove the error handling, the test will fail, alerting you to the problem.

This example demonstrates how to use mocking to verify that logging is occurring when expected during error conditions. In a real application, you would typically have a more robust error handling mechanism, but the principle of logging exceptions remains the same.

In summary, while the original testing code lacked explicit security vulnerabilities, adding proper logging for error conditions as part of the testing process improves the overall robustness and maintainability of the system, and can contribute to preventing unexpected behavior that could indirectly lead to security issues.

---
*Generated by Smart AI Bot*
